Workbook

Sheet USA
A1: Year | B1: Unemployment rate | C1: Nominal GDP | D1: Real GDP | E1: CPI ( base = 1982-84) | F1: Population (thousands) | H1: GDP Deflator | I1: GDP Deflator Index (2000=100) | J1: Real GDP per Capita (USD/person) | K1: Real GDP per Capita Index (2000=100) | L1: Real GDP Growth (%) | M1: Potential GDP (Linear Trend) | N1: Output Gap (%) | O1: CPI Inflation Rate (%) | P1: GDP Deflator Inflation Rate (%) | Q1: Change in Unemployment Rate (pp) | R1: Average Unemployment Rate (%) | S1: Unemployment Gap (pp)
A2: 36526 | B2: 4 | C2: 10250.952 | D2: 14096.033 | E2: 172.192 | F2: 282398 | H2: =C2/D2*100 -> 72.722247 | I2: =H2/$H$2*100 -> 100 | J2: =(D2*1000000000)/(F2*1000) -> 49915.485 | K2: =J2/$J$2*100 -> 100 | M2: {=TREND($D$2:$D$26,$A$2:$A$26,A2)} -> 13714.535 | N2: =(D2-M2)/M2*100 -> 2.7817049 | R2: =AVERAGE($B$2:$B$26) -> 5.704 | S2: =B2-R2 -> -1.704
A3: 36892 | B3: 4.7 | C3: 10581.929 | D3: 14230.726 | E3: 177.042 | F3: 285225 | H3: =C3/D3*100 -> 74.359727 | I3: =H3/$H$2*100 -> 102.25169 | J3: =(D3*1000000000)/(F3*1000) -> 49892.983 | K3: =J3/$J$2*100 -> 99.95492 | L3: =(D3-D2)/D2*100 -> 0.95553834 | M3: {=TREND($D$2:$D$26,$A$2:$A$26,A3)} -> 14076.494 | N3: =(D3-M3)/M3*100 -> 1.0956702 | O3: =(E3-E2)/E2*100 -> 2.8166233 | P3: =(H3-H2)/H2*100 -> 2.2516899 | Q3: =B3-B2 -> 0.7 | R3: =AVERAGE($B$2:$B$26) -> 5.704 | S3: =B3-R3 -> -1.004
A4: 37257 | B4: 5.8 | C4: 10929.108 | D4: 14472.712 | E4: 179.867 | F4: 287955 | H4: =C4/D4*100 -> 75.515273 | I4: =H4/$H$2*100 -> 103.84068 | J4: =(D4*1000000000)/(F4*1000) -> 50260.325 | K4: =J4/$J$2*100 -> 100.69085 | L4: =(D4-D3)/D3*100 -> 1.7004473 | M4: {=TREND($D$2:$D$26,$A$2:$A$26,A4)} -> 14437.464 | N4: =(D4-M4)/M4*100 -> 0.24414229 | O4: =(E4-E3)/E3*100 -> 1.5956666 | P4: =(H4-H3)/H3*100 -> 1.5539947 | Q4: =B4-B3 -> 1.1 | R4: =AVERAGE($B$2:$B$26) -> 5.704 | S4: =B4-R4 -> 0.096
A5: 37622 | B5: 6 | C5: 11456.45 | D5: 14877.313 | E5: 184 | F5: 290626 | H5: =C5/D5*100 -> 77.006177 | I5: =H5/$H$2*100 -> 105.89081 | J5: =(D5*1000000000)/(F5*1000) -> 51190.578 | K5: =J5/$J$2*100 -> 102.55451 | L5: =(D5-D4)/D4*100 -> 2.7956129 | M5: {=TREND($D$2:$D$26,$A$2:$A$26,A5)} -> 14798.434 | N5: =(D5-M5)/M5*100 -> 0.53302239 | O5: =(E5-E4)/E4*100 -> 2.2978089 | P5: =(H5-H4)/H4*100 -> 1.9743079 | Q5: =B5-B4 -> 0.2 | R5: =AVERAGE($B$2:$B$26) -> 5.704 | S5: =B5-R5 -> 0.296
A6: 37987 | B6: 5.5 | C6: 12217.196 | D6: 15449.757 | E6: 188.908 | F6: 293262 | H6: =C6/D6*100 -> 79.076946 | I6: =H6/$H$2*100 -> 108.73831 | J6: =(D6*1000000000)/(F6*1000) -> 52682.438 | K6: =J6/$J$2*100 -> 105.54328 | L6: =(D6-D5)/D5*100 -> 3.8477647 | M6: {=TREND($D$2:$D$26,$A$2:$A$26,A6)} -> 15159.404 | N6: =(D6-M6)/M6*100 -> 1.9153324 | O6: =(E6-E5)/E5*100 -> 2.6673913 | P6: =(H6-H5)/H5*100 -> 2.6890945 | Q6: =B6-B5 -> -0.5 | R6: =AVERAGE($B$2:$B$26) -> 5.704 | S6: =B6-R6 -> -0.204
A7: 38353 | B7: 5.1 | C7: 13039.197 | D7: 15987.958 | E7: 195.267 | F7: 295993 | H7: =C7/D7*100 -> 81.556363 | I7: =H7/$H$2*100 -> 112.14775 | J7: =(D7*1000000000)/(F7*1000) -> 54014.649 | K7: =J7/$J$2*100 -> 108.21221 | L7: =(D7-D6)/D6*100 -> 3.4835564 | M7: {=TREND($D$2:$D$26,$A$2:$A$26,A7)} -> 15521.363 | N7: =(D7-M7)/M7*100 -> 3.0061473 | O7: =(E7-E6)/E6*100 -> 3.3661888 | P7: =(H7-H6)/H6*100 -> 3.1354481 | Q7: =B7-B6 -> -0.4 | R7: =AVERAGE($B$2:$B$26) -> 5.704 | S7: =B7-R7 -> -0.604
A8: 38718 | B8: 4.6 | C8: 13815.583 | D8: 16433.148 | E8: 201.558 | F8: 298818 | H8: =C8/D8*100 -> 84.071433 | I8: =H8/$H$2*100 -> 115.60621 | J8: =(D8*1000000000)/(F8*1000) -> 54993.836 | K8: =J8/$J$2*100 -> 110.1739 | L8: =(D8-D7)/D7*100 -> 2.7845332 | M8: {=TREND($D$2:$D$26,$A$2:$A$26,A8)} -> 15882.333 | N8: =(D8-M8)/M8*100 -> 3.4680991 | O8: =(E8-E7)/E7*100 -> 3.2217425 | P8: =(H8-H7)/H7*100 -> 3.0838432 | Q8: =B8-B7 -> -0.5 | R8: =AVERAGE($B$2:$B$26) -> 5.704 | S8: =B8-R8 -> -1.104
A9: 39083 | B9: 4.6 | C9: 14474.227 | D9: 16762.446 | E9: 207.344 | F9: 301696 | H9: =C9/D9*100 -> 86.349134 | I9: =H9/$H$2*100 -> 118.73826 | J9: =(D9*1000000000)/(F9*1000) -> 55560.717 | K9: =J9/$J$2*100 -> 111.30958 | L9: =(D9-D8)/D8*100 -> 2.0038644 | M9: {=TREND($D$2:$D$26,$A$2:$A$26,A9)} -> 16243.303 | N9: =(D9-M9)/M9*100 -> 3.1960436 | O9: =(E9-E8)/E8*100 -> 2.8706377 | P9: =(H9-H8)/H8*100 -> 2.7092453 | Q9: =B9-B8 -> 0 | R9: =AVERAGE($B$2:$B$26) -> 5.704 | S9: =B9-R9 -> -1.104
A10: 39448 | B10: 5.8 | C10: 14769.862 | D10: 16781.485 | E10: 215.254 | F10: 304543 | H10: =C10/D10*100 -> 88.012843 | I10: =H10/$H$2*100 -> 121.02602 | J10: =(D10*1000000000)/(F10*1000) -> 55103.828 | K10: =J10/$J$2*100 -> 110.39426 | L10: =(D10-D9)/D9*100 -> 0.11358128 | M10: {=TREND($D$2:$D$26,$A$2:$A$26,A10)} -> 16604.273 | N10: =(D10-M10)/M10*100 -> 1.0672678 | O10: =(E10-E9)/E9*100 -> 3.8149163 | P10: =(H10-H9)/H9*100 -> 1.9267228 | Q10: =B10-B9 -> 1.2 | R10: =AVERAGE($B$2:$B$26) -> 5.704 | S10: =B10-R10 -> 0.096
A11: 39814 | B11: 9.3 | C11: 14478.067 | D11: 16349.111 | E11: 214.565 | F11: 307240 | H11: =C11/D11*100 -> 88.555684 | I11: =H11/$H$2*100 -> 121.77248 | J11: =(D11*1000000000)/(F11*1000) -> 53212.834 | K11: =J11/$J$2*100 -> 106.60586 | L11: =(D11-D10)/D10*100 -> -2.5764943 | M11: {=TREND($D$2:$D$26,$A$2:$A$26,A11)} -> 16966.232 | N11: =(D11-M11)/M11*100 -> -3.6373479 | O11: =(E11-E10)/E10*100 -> -0.32008697 | P11: =(H11-H10)/H10*100 -> 0.61677456 | Q11: =B11-B10 -> 3.5 | R11: =AVERAGE($B$2:$B$26) -> 5.704 | S11: =B11-R11 -> 3.596
A12: 40179 | B12: 9.6 | C12: 15048.971 | D12: 16789.751 | E12: 218.076 | F12: 309839 | H12: =C12/D12*100 -> 89.631889 | I12: =H12/$H$2*100 -> 123.25236 | J12: =(D12*1000000000)/(F12*1000) -> 54188.63 | K12: =J12/$J$2*100 -> 108.56076 | L12: =(D12-D11)/D11*100 -> 2.6951924 | M12: {=TREND($D$2:$D$26,$A$2:$A$26,A12)} -> 17327.202 | N12: =(D12-M12)/M12*100 -> -3.1017753 | O12: =(E12-E11)/E11*100 -> 1.636334 | P12: =(H12-H11)/H11*100 -> 1.2152868 | Q12: =B12-B11 -> 0.3 | R12: =AVERAGE($B$2:$B$26) -> 5.704 | S12: =B12-R12 -> 3.896
A13: 40544 | B13: 8.9 | C13: 15599.732 | D13: 17052.411 | E13: 224.923 | F13: 312295 | H13: =C13/D13*100 -> 91.481093 | I13: =H13/$H$2*100 -> 125.7952 | J13: =(D13*1000000000)/(F13*1000) -> 54603.535 | K13: =J13/$J$2*100 -> 109.39198 | L13: =(D13-D12)/D12*100 -> 1.5644068 | M13: {=TREND($D$2:$D$26,$A$2:$A$26,A13)} -> 17688.172 | N13: =(D13-M13)/M13*100 -> -3.5942712 | O13: =(E13-E12)/E12*100 -> 3.1397311 | P13: =(H13-H12)/H12*100 -> 2.0631096 | Q13: =B13-B12 -> -0.7 | R13: =AVERAGE($B$2:$B$26) -> 5.704 | S13: =B13-R13 -> 3.196
A14: 40909 | B14: 8.1 | C14: 16253.97 | D14: 17442.759 | E14: 229.586 | F14: 314725 | H14: =C14/D14*100 -> 93.184628 | I14: =H14/$H$2*100 -> 128.13772 | J14: =(D14*1000000000)/(F14*1000) -> 55422.223 | K14: =J14/$J$2*100 -> 111.03212 | L14: =(D14-D13)/D13*100 -> 2.2891074 | M14: {=TREND($D$2:$D$26,$A$2:$A$26,A14)} -> 18049.142 | N14: =(D14-M14)/M14*100 -> -3.3596215 | O14: =(E14-E13)/E13*100 -> 2.0731539 | P14: =(H14-H13)/H13*100 -> 1.8621709 | Q14: =B14-B13 -> -0.8 | R14: =AVERAGE($B$2:$B$26) -> 5.704 | S14: =B14-R14 -> 2.396
... A26: 45292 | B26: 4 | C26: 29298.013 | D26: 23358.435 | E26: 313.698 | F26: 340095 | H26: =C26/D26*100 -> 125.42798 | I26: =H26/$H$2*100 -> 172.47539 | J26: =(D26*1000000000)/(F26*1000) -> 68682.089 | K26: =J26/$J$2*100 -> 137.59676 | L26: =(D26-D25)/D25*100 -> 2.7931872 | M26: {=TREND($D$2:$D$26,$A$2:$A$26,A26)} -> 22383.749 | N26: =(D26-M26)/M26*100 -> 4.3544377 | O26: =(E26-E25)/E25*100 -> 2.952055 | P26: =(H26-H25)/H25*100 -> 2.4823693 | Q26: =B26-B25 -> 0.4 | R26: =AVERAGE($B$2:$B$26) -> 5.704 | S26: =B26-R26 -> -1.704
A27: Data Sources | B27: FRED `UNRATE` | C27: FRED `GDP` | D27: FRED `GDPC1` | E27: FRED `CPIAUCSL` | F27: FRED `POPTHM` | H27: Excel formula | I27: Excel formula | J27: Excel formula | K27: Excel formula | L27: Excel formula | M27: Excel formula | N27: Excel formula | O27: Excel formula | P27: Excel formula | Q27: Excel formula | R27: Excel formula | S27: Excel formula
H28: Nominal GDP / Real GDP × 100 | I28: GDP Deflator / GDP Deflator in 2000 × 100 | J28: (Real GDP × 1,000,000,000) / (Population × 1,000) | K28: Real GDP per Capita / 2000 value × 100 | L28: (Real GDP_t − Real GDP_t−1) / Real GDP_t−1 × 100 | M28: TREND(Real GDP 2000–2024, time 2000–2024) | N28: (Actual Real GDP − Potential GDP) / Potential GDP × 100 | O28: (CPI_t − CPI_t−1) / CPI_t−1 × 100 | P28: (Deflator_t − Deflator_t−1) / Deflator_t−1 × 100 | Q28: Unemployment_t − Unemployment_t−1 | R28: AVERAGE(Unemployment, 2000–2024) | S28: Actual unemployment − full-sample average
A29: sample period | B29: 2000–2024 | C29: 2000–2024 | D29: 2000–2024 | E29: 2000–2024 | F29: 2000–2024 | G29: valid | H29: 2000–2024 | I29: 2000–2024 | J29: 2000–2024 | K29: 2000–2024 | L29: 2001–2024 | M29: 2000–2024 | N29: 2000–2024 | O29: 2001–2024 | P29: 2001–2024 | Q29: 2001–2024 | R29: 2000–2024 | S29: 2000–2024
A30: type | B30: Monthly unemployment rate (%) | C30: Quarterly GDP, SAAR | D30: Quarterly real GDP, SAAR | E30: Monthly CPI index (1982–1984 = 100) | F30: Monthly population (thousands) | G30: inputs | H30: C, D | I30: H | J30: D, F | K30: J | L30: D | M30: A, D | N30: D, M | O30: E | P30: H | Q30: B | R30: B | S30: B, R
A31: Data processing | B31: Converted to annual using the annual average. | C31: Quarterly SAAR observations were averaged to annual values. | D31: Quarterly SAAR observations were averaged to annual values. | E31: Converted to annual using the annual average. | F31: Converted to annual using the annual average. | G31: purpose | H31: Implicit price index for domestic output. | I31: Re-bases each country's deflator so 2000 = 100 for comparison. | J31: Converts GDP to dollars and population to persons before division. | K31: Measures cumulative real-GDP-per-capita growth since 2000. | L31: Year-over-year real output growth. | M31: Full-sample linear trend used as the homework proxy for potential GDP. | N31: Measures actual output relative to the linear-trend proxy. | O31: Annual CPI inflation. | P31: Annual inflation implied by the GDP deflator. | Q31: Percentage-point change in unemployment; used in Okun scatter plot. | R31: Simple benchmark for the 'normal' unemployment rate in Q9. | S31: Positive values mean unemployment is above its 2000–2024 average.

Sheet Germany
A1: Year | B1: Unemployment rate | C1: Nominal GDP | D1: Real GDP | E1: CPI (base = 2015) | F1: Population(person) | H1: GDP Deflator | I1: GDP Deflator Index (2000=100) | J1: Real GDP per Capita (EUR/person) | K1: Real GDP per Capita Index (2000=100) | L1: Real GDP Growth (%) | M1: Potential GDP (Linear Trend) | N1: Output Gap (%) | O1: CPI Inflation Rate (%) | P1: GDP Deflator Inflation Rate (%) | Q1: Change in Unemployment Rate (pp) | R1: Average Unemployment Rate (%) | S1: Unemployment Gap (pp)
A2: 36526 | B2: 8 | C2: 2129688 | D2: 2395647.2 | E2: 79.943527 | F2: 82211508 | H2: =C2/D2*100 -> 88.898232 | I2: =H2/$H$2*100 -> 100 | J2: =(D2*1000000)/F2 -> 29140.047 | K2: =J2/$J$2*100 -> 100 | M2: {=TREND($D$2:$D$26,$A$2:$A$26,A2)} -> 2346612.9 | N2: =(D2-M2)/M2*100 -> 2.0895782 | R2: =AVERAGE($B$2:$B$26) -> 6.024 | S2: =B2-R2 -> 1.976
A3: 36892 | B3: 7.8 | C3: 2198354 | D3: 2437867.5 | E3: 81.529488 | F3: 82349925 | H3: =C3/D3*100 -> 90.175286 | I3: =H3/$H$2*100 -> 101.43654 | J3: =(D3*1000000)/F3 -> 29603.761 | K3: =J3/$J$2*100 -> 101.59133 | L3: =(D3-D2)/D2*100 -> 1.7623755 | M3: {=TREND($D$2:$D$26,$A$2:$A$26,A3)} -> 2380212.3 | N3: =(D3-M3)/M3*100 -> 2.4222733 | O3: =(E3-E2)/E2*100 -> 1.9838525 | P3: =(H3-H2)/H2*100 -> 1.4365355 | Q3: =B3-B2 -> -0.2 | R3: =AVERAGE($B$2:$B$26) -> 6.024 | S3: =B3-R3 -> 1.776
A4: 37257 | B4: 8.6 | C4: 2227073 | D4: 2433299.2 | E4: 82.687866 | F4: 82488495 | H4: =C4/D4*100 -> 91.524832 | I4: =H4/$H$2*100 -> 102.95461 | J4: =(D4*1000000)/F4 -> 29498.649 | K4: =J4/$J$2*100 -> 101.23062 | L4: =(D4-D3)/D3*100 -> -0.18738918 | M4: {=TREND($D$2:$D$26,$A$2:$A$26,A4)} -> 2413719.8 | N4: =(D4-M4)/M4*100 -> 0.81117041 | O4: =(E4-E3)/E3*100 -> 1.420808 | P4: =(H4-H3)/H3*100 -> 1.4965801 | Q4: =B4-B3 -> 0.8 | R4: =AVERAGE($B$2:$B$26) -> 6.024 | S4: =B4-R4 -> 2.576
A5: 37622 | B5: 9.7 | C5: 2244141 | D5: 2419815.1 | E5: 83.543044 | F5: 82534176 | H5: =C5/D5*100 -> 92.740185 | I5: =H5/$H$2*100 -> 104.32174 | J5: =(D5*1000000)/F5 -> 29318.947 | K5: =J5/$J$2*100 -> 100.61393 | L5: =(D5-D4)/D4*100 -> -0.55414887 | M5: {=TREND($D$2:$D$26,$A$2:$A$26,A5)} -> 2447227.4 | N5: =(D5-M5)/M5*100 -> -1.1201363 | O5: =(E5-E4)/E4*100 -> 1.0342247 | P5: =(H5-H4)/H4*100 -> 1.3278945 | Q5: =B5-B4 -> 1.1 | R5: =AVERAGE($B$2:$B$26) -> 6.024 | S5: =B5-R5 -> 3.676
A6: 37987 | B6: 10.3 | C6: 2285493 | D6: 2436467.6 | E6: 84.934648 | F6: 82516260 | H6: =C6/D6*100 -> 93.803546 | I6: =H6/$H$2*100 -> 105.5179 | J6: =(D6*1000000)/F6 -> 29527.121 | K6: =J6/$J$2*100 -> 101.32832 | L6: =(D6-D5)/D5*100 -> 0.68817241 | M6: {=TREND($D$2:$D$26,$A$2:$A$26,A6)} -> 2480734.9 | N6: =(D6-M6)/M6*100 -> -1.7844449 | O6: =(E6-E5)/E5*100 -> 1.6657331 | P6: =(H6-H5)/H5*100 -> 1.146602 | Q6: =B6-B5 -> 0.6 | R6: =AVERAGE($B$2:$B$26) -> 6.024 | S6: =B6-R6 -> 4.276
A7: 38353 | B7: 11 | C7: 2322042 | D7: 2462256.5 | E7: 86.248512 | F7: 82469422 | H7: =C7/D7*100 -> 94.305447 | I7: =H7/$H$2*100 -> 106.08248 | J7: =(D7*1000000)/F7 -> 29856.599 | K7: =J7/$J$2*100 -> 102.459 | L7: =(D7-D6)/D6*100 -> 1.0584545 | M7: {=TREND($D$2:$D$26,$A$2:$A$26,A7)} -> 2514334.3 | N7: =(D7-M7)/M7*100 -> -2.0712366 | O7: =(E7-E6)/E6*100 -> 1.5469109 | P7: =(H7-H6)/H6*100 -> 0.53505579 | Q7: =B7-B6 -> 0.7 | R7: =AVERAGE($B$2:$B$26) -> 6.024 | S7: =B7-R7 -> 4.976
A8: 38718 | B8: 10.1 | C8: 2426834 | D8: 2561949.3 | E8: 87.609024 | F8: 82376451 | H8: =C8/D8*100 -> 94.726074 | I8: =H8/$H$2*100 -> 106.55563 | J8: =(D8*1000000)/F8 -> 31100.506 | K8: =J8/$J$2*100 -> 106.72771 | L8: =(D8-D7)/D7*100 -> 4.0488389 | M8: {=TREND($D$2:$D$26,$A$2:$A$26,A8)} -> 2547841.9 | N8: =(D8-M8)/M8*100 -> 0.55370088 | O8: =(E8-E7)/E7*100 -> 1.577433 | P8: =(H8-H7)/H7*100 -> 0.44602656 | Q8: =B8-B7 -> -0.9 | R8: =AVERAGE($B$2:$B$26) -> 6.024 | S8: =B8-R8 -> 4.076
A9: 39083 | B9: 8.6 | C9: 2545653 | D9: 2638874.1 | E9: 89.622573 | F9: 82266372 | H9: =C9/D9*100 -> 96.467391 | I9: =H9/$H$2*100 -> 108.51441 | J9: =(D9*1000000)/F9 -> 32077.191 | K9: =J9/$J$2*100 -> 110.07941 | L9: =(D9-D8)/D8*100 -> 3.0025887 | M9: {=TREND($D$2:$D$26,$A$2:$A$26,A9)} -> 2581349.4 | N9: =(D9-M9)/M9*100 -> 2.2284724 | O9: =(E9-E8)/E8*100 -> 2.2983353 | P9: =(H9-H8)/H8*100 -> 1.8382655 | Q9: =B9-B8 -> -1.5 | R9: =AVERAGE($B$2:$B$26) -> 6.024 | S9: =B9-R9 -> 2.576
A10: 39448 | B10: 7.4 | C10: 2585733 | D10: 2654937 | E10: 91.978202 | F10: 82110097 | H10: =C10/D10*100 -> 97.393384 | I10: =H10/$H$2*100 -> 109.55604 | J10: =(D10*1000000)/F10 -> 32333.868 | K10: =J10/$J$2*100 -> 110.96025 | L10: =(D10-D9)/D9*100 -> 0.60870278 | M10: {=TREND($D$2:$D$26,$A$2:$A$26,A10)} -> 2614857 | N10: =(D10-M10)/M10*100 -> 1.5327796 | O10: =(E10-E9)/E9*100 -> 2.6283882 | P10: =(H10-H9)/H9*100 -> 0.95990294 | Q10: =B10-B9 -> -1.2 | R10: =AVERAGE($B$2:$B$26) -> 6.024 | S10: =B10-R10 -> 1.376
A11: 39814 | B11: 7.4 | C11: 2491785 | D11: 2509045.1 | E11: 92.265852 | F11: 81902307 | H11: =C11/D11*100 -> 99.312085 | I11: =H11/$H$2*100 -> 111.71435 | J11: =(D11*1000000)/F11 -> 30634.608 | K11: =J11/$J$2*100 -> 105.12889 | L11: =(D11-D10)/D10*100 -> -5.4951172 | M11: {=TREND($D$2:$D$26,$A$2:$A$26,A11)} -> 2648456.4 | N11: =(D11-M11)/M11*100 -> -5.2638689 | O11: =(E11-E10)/E10*100 -> 0.31273714 | P11: =(H11-H10)/H10*100 -> 1.9700521 | Q11: =B11-B10 -> 0 | R11: =AVERAGE($B$2:$B$26) -> 6.024 | S11: =B11-R11 -> 1.376
A12: 40179 | B12: 6.6 | C12: 2609401 | D12: 2609401 | E12: 93.284289 | F12: 81776930 | H12: =C12/D12*100 -> 100 | I12: =H12/$H$2*100 -> 112.48818 | J12: =(D12*1000000)/F12 -> 31908.767 | K12: =J12/$J$2*100 -> 109.50143 | L12: =(D12-D11)/D11*100 -> 3.9997647 | M12: {=TREND($D$2:$D$26,$A$2:$A$26,A12)} -> 2681963.9 | N12: =(D12-M12)/M12*100 -> -2.7055895 | O12: =(E12-E11)/E11*100 -> 1.1038067 | P12: =(H12-H11)/H11*100 -> 0.69268015 | Q12: =B12-B11 -> -0.8 | R12: =AVERAGE($B$2:$B$26) -> 6.024 | S12: =B12-R12 -> 0.576
A13: 40544 | B13: 5.5 | C13: 2743043 | D13: 2709683.2 | E13: 95.220101 | F13: 80274983 | H13: =C13/D13*100 -> 101.23113 | I13: =H13/$H$2*100 -> 113.87306 | J13: =(D13*1000000)/F13 -> 33755.014 | K13: =J13/$J$2*100 -> 115.8372 | L13: =(D13-D12)/D12*100 -> 3.8431119 | M13: {=TREND($D$2:$D$26,$A$2:$A$26,A13)} -> 2715471.5 | N13: =(D13-M13)/M13*100 -> -0.21316001 | O13: =(E13-E12)/E12*100 -> 2.0751744 | P13: =(H13-H12)/H12*100 -> 1.2311328 | Q13: =B13-B12 -> -1.1 | R13: =AVERAGE($B$2:$B$26) -> 6.024 | S13: =B13-R13 -> -0.524
A14: 40909 | B14: 5.1 | C14: 2802015 | D14: 2728840.6 | E14: 97.132587 | F14: 80425823 | H14: =C14/D14*100 -> 102.68152 | I14: =H14/$H$2*100 -> 115.50457 | J14: =(D14*1000000)/F14 -> 33929.906 | K14: =J14/$J$2*100 -> 116.43738 | L14: =(D14-D13)/D13*100 -> 0.70699778 | M14: {=TREND($D$2:$D$26,$A$2:$A$26,A14)} -> 2748979.1 | N14: =(D14-M14)/M14*100 -> -0.73257973 | O14: =(E14-E13)/E13*100 -> 2.0084896 | P14: =(H14-H13)/H13*100 -> 1.4327479 | Q14: =B14-B13 -> -0.4 | R14: =AVERAGE($B$2:$B$26) -> 6.024 | S14: =B14-R14 -> -0.924
... A26: 45292 | B26: 3.4 | C26: 4389409 | D26: 3091433.5 | E26: 125.81121 | F26: 83516593 | H26: =C26/D26*100 -> 141.9862 | I26: =H26/$H$2*100 -> 159.71769 | J26: =(D26*1000000)/F26 -> 37015.8 | K26: =J26/$J$2*100 -> 127.02725 | L26: =(D26-D25)/D25*100 -> 0.040531606 | M26: {=TREND($D$2:$D$26,$A$2:$A$26,A26)} -> 3151345.2 | N26: =(D26-M26)/M26*100 -> -1.901148 | O26: =(E26-E25)/E25*100 -> 2.2564933 | P26: =(H26-H25)/H25*100 -> 3.092413 | Q26: =B26-B25 -> 0.3 | R26: =AVERAGE($B$2:$B$26) -> 6.024 | S26: =B26-R26 -> -2.624
A27: Data Sources | B27: FRED `LRHUTTTTDEM156S` | C27: FRED `CPMNACSCAB1GQDE` | D27: FRED `CLVMNACSCAB1GQDE` | E27: FRED `DEUCPIALLMINMEI` | F27: FRED `POPTOTDEA647NWDB` | H27: Excel formula | I27: Excel formula | J27: Excel formula | K27: Excel formula | L27: Excel formula | M27: Excel formula | N27: Excel formula | O27: Excel formula | P27: Excel formula | Q27: Excel formula | R27: Excel formula | S27: Excel formula
H28: Nominal GDP / Real GDP × 100 | I28: GDP Deflator / GDP Deflator in 2000 × 100 | J28: (Real GDP × 1,000,000) / Population → EUR/person | K28: Real GDP per Capita / 2000 value × 100 | L28: (Real GDP_t − Real GDP_t−1) / Real GDP_t−1 × 100 | M28: TREND(Real GDP 2000–2024, time 2000–2024) | N28: (Actual Real GDP − Potential GDP) / Potential GDP × 100 | O28: (CPI_t − CPI_t−1) / CPI_t−1 × 100 | P28: (Deflator_t − Deflator_t−1) / Deflator_t−1 × 100 | Q28: Unemployment_t − Unemployment_t−1 | R28: AVERAGE(Unemployment, 2000–2024) | S28: Actual unemployment − full-sample average
A29: sample period | B29: 2000–2024 | C29: 2000–2024 | D29: 2000–2024 | E29: 2000–2024 | F29: 2000–2024 | G29: valid | H29: 2000–2024 | I29: 2000–2024 | J29: 2000–2024 | K29: 2000–2024 | L29: 2001–2024 | M29: 2000–2024 | N29: 2000–2024 | O29: 2001–2024 | P29: 2001–2024 | Q29: 2001–2024 | R29: 2000–2024 | S29: 2000–2024
A30: type | B30: Monthly harmonized unemployment rate (%) | C30: Quarterly nominal GDP (million EUR) | D30: Quarterly real GDP (million chained EUR) | E30: Monthly CPI index (2015 = 100) | F30: Annual population (persons) | G30: inputs | H30: C, D | I30: H | J30: D, F | K30: J | L30: D | M30: A, D | N30: D, M | O30: E | P30: H | Q30: B | R30: B | S30: B, R
A31: Data processing | B31: Converted to annual using the annual average. | C31: Four quarterly values were summed to obtain each annual GDP value. | D31: Four quarterly values were summed to obtain each annual real GDP value. | E31: Converted to annual using the annual average. | F31: Already annual; no frequency conversion. | G31: purpose | H31: Implicit price index for domestic output. | I31: Re-bases each country's deflator so 2000 = 100 for comparison. | J31: Converts GDP from millions of EUR to EUR before dividing by persons. | K31: Measures cumulative real-GDP-per-capita growth since 2000. | L31: Year-over-year real output growth. | M31: Full-sample linear trend used as the homework proxy for potential GDP. | N31: Measures actual output relative to the linear-trend proxy. | O31: Annual CPI inflation. | P31: Annual inflation implied by the GDP deflator. | Q31: Percentage-point change in unemployment; used in Okun scatter plot. | R31: Simple benchmark for the 'normal' unemployment rate in Q9. | S31: Positive values mean unemployment is above its 2000–2024 average.

Sheet China
A1: Year | B1: Youth Unemployment Rate (%) | C1: Nominal GDP (million yuan) | D1: Real GDP - Reconstructed (million yuan, base 2000) | E1: CPI (2015=100) | F1: Population (persons) | G1: Real GDP Growth Input (%) | I1: GDP Deflator | J1: GDP Deflator Index (2000=100) | K1: Real GDP per Capita (Yuan/person) | L1: Real GDP per Capita Index (2000=100) | M1: Real GDP Growth (%) | N1: Potential GDP (Linear Trend) | O1: Output Gap (%) | P1: CPI Inflation Rate (%) | Q1: GDP Deflator Inflation Rate (%) | R1: Change in Unemployment Rate (pp) | S1: Average Unemployment Rate (%) | T1: Unemployment Gap (pp)
A2: 36526 | B2: 6.84 | C2: 10130860 | D2: =C2 -> 10130860 | E2: 70.456424 | F2: 1262645000 | G2: 8.6 | I2: =C2/D2*100 -> 100 | J2: =I2/$I$2*100 -> 100 | K2: =(D2*1000000)/F2 -> 8023.5221 | L2: =K2/$K$2*100 -> 100 | N2: {=TREND($D$2:$D$26,$A$2:$A$26,A2)} -> 5169482.5 | O2: =(D2-N2)/N2*100 -> 95.974353 | S2: =AVERAGE($B$2:$B$26) -> 10.55848 | T2: =B2-S2 -> -3.71848
A3: 36892 | B3: 7.994 | C3: 11215730 | D3: =D2*(1+G3/100) -> 10971721 | E3: 70.963099 | F3: 1271850000 | G3: 8.3 | I3: =C3/D3*100 -> 102.22398 | J3: =I3/$I$2*100 -> 102.22398 | K3: =(D3*1000000)/F3 -> 8626.5844 | L3: =K3/$K$2*100 -> 107.51618 | M3: =(D3-D2)/D2*100 -> 8.3 | N3: {=TREND($D$2:$D$26,$A$2:$A$26,A3)} -> 7614700.5 | O3: =(D3-N3)/N3*100 -> 44.086052 | P3: =(E3-E2)/E2*100 -> 0.71913244 | Q3: =(I3-I2)/I2*100 -> 2.2239775 | R3: =B3-B2 -> 1.154 | S3: =AVERAGE($B$2:$B$26) -> 10.55848 | T3: =B3-S3 -> -2.56448
A4: 37257 | B4: 8.919 | C4: 12331180 | D4: =D3*(1+G4/100) -> 11981120 | E4: 70.443667 | F4: 1280400000 | G4: 9.2 | I4: =C4/D4*100 -> 102.92177 | J4: =I4/$I$2*100 -> 102.92177 | K4: =(D4*1000000)/F4 -> 9357.3256 | L4: =K4/$K$2*100 -> 116.62367 | M4: =(D4-D3)/D3*100 -> 9.2 | N4: {=TREND($D$2:$D$26,$A$2:$A$26,A4)} -> 10053238 | O4: =(D4-N4)/N4*100 -> 19.176729 | P4: =(E4-E3)/E3*100 -> -0.7319755 | Q4: =(I4-I3)/I3*100 -> 0.68260717 | R4: =B4-B3 -> 0.925 | S4: =AVERAGE($B$2:$B$26) -> 10.55848 | T4: =B4-S4 -> -1.63948
A5: 37622 | B5: 9.624 | C5: 13937730 | D5: =D4*(1+G5/100) -> 13191213 | E5: 71.237991 | F5: 1288400000 | G5: 10.1 | I5: =C5/D5*100 -> 105.6592 | J5: =I5/$I$2*100 -> 105.6592 | K5: =(D5*1000000)/F5 -> 10238.445 | L5: =K5/$K$2*100 -> 127.60537 | M5: =(D5-D4)/D4*100 -> 10.1 | N5: {=TREND($D$2:$D$26,$A$2:$A$26,A5)} -> 12491775 | O5: =(D5-N5)/N5*100 -> 5.5991902 | P5: =(E5-E4)/E4*100 -> 1.127602 | Q5: =(I5-I4)/I4*100 -> 2.6597237 | R5: =B5-B4 -> 0.705 | S5: =AVERAGE($B$2:$B$26) -> 10.55848 | T5: =B5-S5 -> -0.93448
A6: 37987 | B6: 9.433 | C6: 16422790 | D6: =D5*(1+G6/100) -> 14523525 | E6: 73.962586 | F6: 1296075000 | G6: 10.1 | I6: =C6/D6*100 -> 113.07716 | J6: =I6/$I$2*100 -> 113.07716 | K6: =(D6*1000000)/F6 -> 11205.775 | L6: =K6/$K$2*100 -> 139.66155 | M6: =(D6-D5)/D5*100 -> 10.1 | N6: {=TREND($D$2:$D$26,$A$2:$A$26,A6)} -> 14930312 | O6: =(D6-N6)/N6*100 -> -2.7245669 | P6: =(E6-E5)/E5*100 -> 3.8246376 | Q6: =(I6-I5)/I5*100 -> 7.0206473 | R6: =B6-B5 -> -0.191 | S6: =AVERAGE($B$2:$B$26) -> 10.55848 | T6: =B6-S6 -> -1.12548
A7: 38353 | B7: 9.495 | C7: 18990750 | D7: =D6*(1+G7/100) -> 16193731 | E7: 75.276469 | F7: 1303720000 | G7: 11.5 | I7: =C7/D7*100 -> 117.27224 | J7: =I7/$I$2*100 -> 117.27224 | K7: =(D7*1000000)/F7 -> 12421.172 | L7: =K7/$K$2*100 -> 154.80947 | M7: =(D7-D6)/D6*100 -> 11.5 | N7: {=TREND($D$2:$D$26,$A$2:$A$26,A7)} -> 17375530 | O7: =(D7-N7)/N7*100 -> -6.8015129 | P7: =(E7-E6)/E6*100 -> 1.7764162 | Q7: =(I7-I6)/I6*100 -> 3.7099225 | R7: =B7-B6 -> 0.062 | S7: =AVERAGE($B$2:$B$26) -> 10.55848 | T7: =B7-S7 -> -1.06348
A8: 38718 | B8: 9.331 | C8: 22257830 | D8: =D7*(1+G8/100) -> 18250335 | E8: 76.518104 | F8: 1311020000 | G8: 12.7 | I8: =C8/D8*100 -> 121.95848 | J8: =I8/$I$2*100 -> 121.95848 | K8: =(D8*1000000)/F8 -> 13920.714 | L8: =K8/$K$2*100 -> 173.49879 | M8: =(D8-D7)/D7*100 -> 12.7 | N8: {=TREND($D$2:$D$26,$A$2:$A$26,A8)} -> 19814067 | O8: =(D8-N8)/N8*100 -> -7.8920303 | P8: =(E8-E7)/E7*100 -> 1.6494331 | Q8: =(I8-I7)/I7*100 -> 3.9960366 | R8: =B8-B7 -> -0.164 | S8: =AVERAGE($B$2:$B$26) -> 10.55848 | T8: =B8-S8 -> -1.22748
A9: 39083 | B9: 9.224 | C9: 27417970 | D9: =D8*(1+G9/100) -> 20841882 | E9: 80.203802 | F9: 1317885000 | G9: 14.2 | I9: =C9/D9*100 -> 131.55227 | J9: =I9/$I$2*100 -> 131.55227 | K9: =(D9*1000000)/F9 -> 15814.644 | L9: =K9/$K$2*100 -> 197.10351 | M9: =(D9-D8)/D8*100 -> 14.2 | N9: {=TREND($D$2:$D$26,$A$2:$A$26,A9)} -> 22252604 | O9: =(D9-N9)/N9*100 -> -6.3395803 | P9: =(E9-E8)/E8*100 -> 4.8167653 | Q9: =(I9-I8)/I8*100 -> 7.8664465 | R9: =B9-B8 -> -0.107 | S9: =AVERAGE($B$2:$B$26) -> 10.55848 | T9: =B9-S9 -> -1.33448
A10: 39448 | B10: 9.803 | C10: 32431790 | D10: =D9*(1+G10/100) -> 22863545 | E10: 84.956082 | F10: 1324655000 | G10: 9.7 | I10: =C10/D10*100 -> 141.84935 | J10: =I10/$I$2*100 -> 141.84935 | K10: =(D10*1000000)/F10 -> 17259.999 | L10: =K10/$K$2*100 -> 215.11749 | M10: =(D10-D9)/D9*100 -> 9.7 | N10: {=TREND($D$2:$D$26,$A$2:$A$26,A10)} -> 24691141 | O10: =(D10-N10)/N10*100 -> -7.4018296 | P10: =(E10-E9)/E9*100 -> 5.9252553 | Q10: =(I10-I9)/I9*100 -> 7.8273656 | R10: =B10-B9 -> 0.579 | S10: =AVERAGE($B$2:$B$26) -> 10.55848 | T10: =B10-S10 -> -0.75548
A11: 39814 | B11: 10.15 | C11: 35452160 | D11: =D10*(1+G11/100) -> 25012718 | E11: 84.337456 | F11: 1331260000 | G11: 9.4 | I11: =C11/D11*100 -> 141.73654 | J11: =I11/$I$2*100 -> 141.73654 | K11: =(D11*1000000)/F11 -> 18788.755 | L11: =K11/$K$2*100 -> 234.17091 | M11: =(D11-D10)/D10*100 -> 9.4 | N11: {=TREND($D$2:$D$26,$A$2:$A$26,A11)} -> 27136359 | O11: =(D11-N11)/N11*100 -> -7.825814 | P11: =(E11-E10)/E10*100 -> -0.72817133 | Q11: =(I11-I10)/I10*100 -> -0.079532016 | R11: =B11-B10 -> 0.347 | S11: =AVERAGE($B$2:$B$26) -> 10.55848 | T11: =B11-S11 -> -0.40848
A12: 40179 | B12: 9.823 | C12: 41925330 | D12: =D11*(1+G12/100) -> 27664066 | E12: 87.015447 | F12: 1337705000 | G12: 10.6 | I12: =C12/D12*100 -> 151.55158 | J12: =I12/$I$2*100 -> 151.55158 | K12: =(D12*1000000)/F12 -> 20680.244 | L12: =K12/$K$2*100 -> 257.74521 | M12: =(D12-D11)/D11*100 -> 10.6 | N12: {=TREND($D$2:$D$26,$A$2:$A$26,A12)} -> 29574896 | O12: =(D12-N12)/N12*100 -> -6.4609861 | P12: =(E12-E11)/E11*100 -> 3.175328 | Q12: =(I12-I11)/I11*100 -> 6.924853 | R12: =B12-B11 -> -0.327 | S12: =AVERAGE($B$2:$B$26) -> 10.55848 | T12: =B12-S12 -> -0.73548
A13: 40544 | B13: 9.976 | C13: 49570750 | D13: =D12*(1+G13/100) -> 30292152 | E13: 91.848195 | F13: 1345035000 | G13: 9.5 | I13: =C13/D13*100 -> 163.64222 | J13: =I13/$I$2*100 -> 163.64222 | K13: =(D13*1000000)/F13 -> 22521.46 | L13: =K13/$K$2*100 -> 280.69294 | M13: =(D13-D12)/D12*100 -> 9.5 | N13: {=TREND($D$2:$D$26,$A$2:$A$26,A13)} -> 32013433 | O13: =(D13-N13)/N13*100 -> -5.3767452 | P13: =(E13-E12)/E12*100 -> 5.5538971 | Q13: =(I13-I12)/I12*100 -> 7.977901 | R13: =B13-B12 -> 0.153 | S13: =AVERAGE($B$2:$B$26) -> 10.55848 | T13: =B13-S13 -> -0.58248
A14: 40909 | B14: 10.154 | C14: 54751070 | D14: =D13*(1+G14/100) -> 32685232 | E14: 94.254182 | F14: 1354190000 | G14: 7.9 | I14: =C14/D14*100 -> 167.51011 | J14: =I14/$I$2*100 -> 167.51011 | K14: =(D14*1000000)/F14 -> 24136.371 | L14: =K14/$K$2*100 -> 300.82015 | M14: =(D14-D13)/D13*100 -> 7.9 | N14: {=TREND($D$2:$D$26,$A$2:$A$26,A14)} -> 34451970 | O14: =(D14-N14)/N14*100 -> -5.1281182 | P14: =(E14-E13)/E13*100 -> 2.6195262 | Q14: =(I14-I13)/I13*100 -> 2.3636296 | R14: =B14-B13 -> 0.178 | S14: =AVERAGE($B$2:$B$26) -> 10.55848 | T14: =B14-S14 -> -0.40448
... A26: 45292 | B26: 15.044 | C26: 134806620 | D26: =D25*(1+G26/100) -> 66464877 | E26: 115.31077 | F26: 1408975000 | G26: 5 | I26: =C26/D26*100 -> 202.82385 | J26: =I26/$I$2*100 -> 202.82385 | K26: =(D26*1000000)/F26 -> 47172.503 | L26: =K26/$K$2*100 -> 587.92763 | M26: =(D26-D25)/D25*100 -> 5 | N26: {=TREND($D$2:$D$26,$A$2:$A$26,A26)} -> 63734457 | O26: =(D26-N26)/N26*100 -> 4.2840559 | P26: =(E26-E25)/E25*100 -> 0.21812572 | Q26: =(I26-I25)/I25*100 -> -0.80348104 | R26: =B26-B25 -> -0.518 | S26: =AVERAGE($B$2:$B$26) -> 10.55848 | T26: =B26-S26 -> 4.48552
A27: Data Sources | B27: FRED `SLUEM1524ZSCHN` | C27: FRED `NGDPXDCCNA` | D27: Reconstructed from FRED `CHNGDPRAPSMEI` | E27: FRED `CHNCPIALLMINMEI` | F27: FRED `POPTOTCNA647NWDB` | G27: FRED `CHNGDPRAPSMEI` | I27: Excel formula | J27: Excel formula | K27: Excel formula | L27: Excel formula | M27: Excel formula | N27: Excel formula | O27: Excel formula | P27: Excel formula | Q27: Excel formula | R27: Excel formula | S27: Excel formula | T27: Excel formula
I28: Nominal GDP / Reconstructed Real GDP × 100 | J28: GDP Deflator / GDP Deflator in 2000 × 100 | K28: (Reconstructed Real GDP × 1,000,000) / Population → Yuan/person | L28: Real GDP per Capita / 2000 value × 100 | M28: (Real GDP_t − Real GDP_t−1) / Real GDP_t−1 × 100 | N28: TREND(Reconstructed Real GDP 2000–2024, time 2000–2024) | O28: (Actual Real GDP − Potential GDP) / Potential GDP × 100 | P28: (CPI_t − CPI_t−1) / CPI_t−1 × 100 | Q28: (Deflator_t − Deflator_t−1) / Deflator_t−1 × 100 | R28: Youth unemployment_t − Youth unemployment_t−1 | S28: AVERAGE(Youth unemployment, 2000–2024) | T28: Actual youth unemployment − full-sample average
A29: sample period | B29: 2000–2024 | C29: 2000–2024 | D29: 2000–2024 | E29: 2000–2024 | F29: 2000–2024 | G29: 2000–2024 | H29: valid | I29: 2000–2024 | J29: 2000–2024 | K29: 2000–2024 | L29: 2000–2024 | M29: 2001–2024 | N29: 2000–2024 | O29: 2000–2024 | P29: 2001–2024 | Q29: 2001–2024 | R29: 2001–2024 | S29: 2000–2024 | T29: 2000–2024
A30: type | B30: Annual youth unemployment rate, ages 15–24 (%) | C30: Annual nominal GDP (million yuan) | D30: Reconstructed real GDP level | E30: Monthly CPI index (2015 = 100) | F30: Annual population (persons) | G30: Annual real GDP growth rate (%) | H30: inputs | I30: C, D | J30: I | K30: D, F | L30: K | M30: D | N30: A, D | O30: D, N | P30: E | Q30: I | R30: B | S30: B | T30: B, S
A31: Data processing | B31: Already annual; no frequency conversion. | C31: Already annual; no frequency conversion. | D31: 2000 was used as the base/start value; later real GDP values were chained using the annual real GDP growth rate. | E31: Converted to annual using the annual average. | F31: Already annual; no frequency conversion. | G31: Already annual; used as the input for real GDP reconstruction. | H31: purpose | I31: Implicit price index based on the reconstructed real-GDP series. | J31: Re-bases the deflator so 2000 = 100 for comparison. | K31: Converts GDP from million yuan to yuan before dividing by persons. | L31: Measures cumulative real-GDP-per-capita growth since 2000. | M31: Year-over-year growth of the reconstructed real-GDP series. | N31: Full-sample linear trend used as the homework proxy for potential GDP. | O31: Measures actual output relative to the linear-trend proxy. | P31: Annual CPI inflation. | Q31: Annual inflation implied by the reconstructed GDP deflator. | R31: Percentage-point change in the selected youth-unemployment series. | S31: Simple benchmark for the selected unemployment series in Q9. | T31: Positive values mean youth unemployment is above its sample average.

Sheet Italy
A1: Year | B1: Unemployment rate | C1: Nominal GDP | D1: Real GDP | E1: CPI( base = 2015) | F1: Population(person) | H1: GDP Deflator | I1: GDP Deflator Index (2000=100) | J1: Real GDP per Capita (EUR/person) | K1: Real GDP per Capita Index (2000=100) | L1: Real GDP Growth (%) | M1: Potential GDP (Linear Trend) | N1: Output Gap (%) | O1: CPI Inflation Rate (%) | P1: GDP Deflator Inflation Rate (%) | Q1: Change in Unemployment Rate (pp) | R1: Average Unemployment Rate (%) | S1: Unemployment Gap (pp)
A2: 36526 | B2: 10.1 | C2: 1245557 | D2: 1573989 | E2: 75.057391 | F2: 56942108 | H2: =C2/D2*100 -> 79.13378 | I2: =H2/$H$2*100 -> 100 | J2: =(D2*1000000)/F2 -> 27641.917 | K2: =J2/$J$2*100 -> 100 | M2: {=TREND($D$2:$D$26,$A$2:$A$26,A2)} -> 1609949.5 | N2: =(D2-M2)/M2*100 -> -2.2336395 | R2: =AVERAGE($B$2:$B$26) -> 9.2 | S2: =B2-R2 -> 0.9
A3: 36892 | B3: 9.1 | C3: 1307586 | D3: 1603251.6 | E3: 77.147863 | F3: 56976981 | H3: =C3/D3*100 -> 81.558378 | I3: =H3/$H$2*100 -> 103.06392 | J3: =(D3*1000000)/F3 -> 28138.585 | K3: =J3/$J$2*100 -> 101.79679 | L3: =(D3-D2)/D2*100 -> 1.8591362 | M3: {=TREND($D$2:$D$26,$A$2:$A$26,A3)} -> 1610755.6 | N3: =(D3-M3)/M3*100 -> -0.46586673 | O3: =(E3-E2)/E2*100 -> 2.7851654 | P3: =(H3-H2)/H2*100 -> 3.0639223 | Q3: =B3-B2 -> -1 | R3: =AVERAGE($B$2:$B$26) -> 9.2 | S3: =B3-R3 -> -0.1
A4: 37257 | B4: 8.6 | C4: 1354153 | D4: 1607214.9 | E4: 79.049808 | F4: 57089824 | H4: =C4/D4*100 -> 84.254632 | I4: =H4/$H$2*100 -> 106.47113 | J4: =(D4*1000000)/F4 -> 28152.388 | K4: =J4/$J$2*100 -> 101.84673 | L4: =(D4-D3)/D3*100 -> 0.24720387 | M4: {=TREND($D$2:$D$26,$A$2:$A$26,A4)} -> 1611559.5 | N4: =(D4-M4)/M4*100 -> -0.26958847 | O4: =(E4-E3)/E3*100 -> 2.4653232 | P4: =(H4-H3)/H3*100 -> 3.3059192 | Q4: =B4-B3 -> -0.5 | R4: =AVERAGE($B$2:$B$26) -> 9.2 | S4: =B4-R4 -> -0.6
A5: 37622 | B5: 8.5 | C5: 1399084 | D5: 1609558.9 | E5: 81.162458 | F5: 57399184 | H5: =C5/D5*100 -> 86.923442 | I5: =H5/$H$2*100 -> 109.84366 | J5: =(D5*1000000)/F5 -> 28041.494 | K5: =J5/$J$2*100 -> 101.44555 | L5: =(D5-D4)/D4*100 -> 0.14584235 | M5: {=TREND($D$2:$D$26,$A$2:$A$26,A5)} -> 1612363.4 | N5: =(D5-M5)/M5*100 -> -0.17393616 | O5: =(E5-E4)/E4*100 -> 2.6725555 | P5: =(H5-H4)/H4*100 -> 3.167553 | Q5: =B5-B4 -> -0.1 | R5: =AVERAGE($B$2:$B$26) -> 9.2 | S5: =B5-R5 -> -0.7
A6: 37987 | B6: 8 | C6: 1453947 | D6: 1629745.2 | E6: 82.953499 | F6: 57828179 | H6: =C6/D6*100 -> 89.213148 | I6: =H6/$H$2*100 -> 112.73712 | J6: =(D6*1000000)/F6 -> 28182.544 | K6: =J6/$J$2*100 -> 101.95582 | L6: =(D6-D5)/D5*100 -> 1.2541511 | M6: {=TREND($D$2:$D$26,$A$2:$A$26,A6)} -> 1613167.3 | N6: =(D6-M6)/M6*100 -> 1.0276623 | O6: =(E6-E5)/E5*100 -> 2.2067366 | P6: =(H6-H5)/H5*100 -> 2.6341639 | Q6: =B6-B5 -> -0.5 | R6: =AVERAGE($B$2:$B$26) -> 9.2 | S6: =B6-R6 -> -1.2
A7: 38353 | B7: 7.8 | C7: 1501176 | D7: 1648378.7 | E7: 84.600369 | F7: 58166682 | H7: =C7/D7*100 -> 91.069849 | I7: =H7/$H$2*100 -> 115.08341 | J7: =(D7*1000000)/F7 -> 28338.881 | K7: =J7/$J$2*100 -> 102.52141 | L7: =(D7-D6)/D6*100 -> 1.1433382 | M7: {=TREND($D$2:$D$26,$A$2:$A$26,A7)} -> 1613973.4 | N7: =(D7-M7)/M7*100 -> 2.1317146 | O7: =(E7-E6)/E6*100 -> 1.985293 | P7: =(H7-H6)/H6*100 -> 2.0811969 | Q7: =B7-B6 -> -0.2 | R7: =AVERAGE($B$2:$B$26) -> 9.2 | S7: =B7-R7 -> -1.4
A8: 38718 | B8: 6.9 | C8: 1563447 | D8: 1679634.6 | E8: 86.369231 | F8: 58399861 | H8: =C8/D8*100 -> 93.082567 | I8: =H8/$H$2*100 -> 117.62684 | J8: =(D8*1000000)/F8 -> 28760.935 | K8: =J8/$J$2*100 -> 104.04827 | L8: =(D8-D7)/D7*100 -> 1.8961601 | M8: {=TREND($D$2:$D$26,$A$2:$A$26,A8)} -> 1614777.3 | N8: =(D8-M8)/M8*100 -> 4.0164858 | O8: =(E8-E7)/E7*100 -> 2.0908439 | P8: =(H8-H7)/H7*100 -> 2.210081 | Q8: =B8-B7 -> -0.9 | R8: =AVERAGE($B$2:$B$26) -> 9.2 | S8: =B8-R8 -> -2.3
A9: 39083 | B9: 6.2 | C9: 1622562 | D9: 1701173.5 | E9: 87.949564 | F9: 58756247 | H9: =C9/D9*100 -> 95.378984 | I9: =H9/$H$2*100 -> 120.52878 | J9: =(D9*1000000)/F9 -> 28953.066 | K9: =J9/$J$2*100 -> 104.74334 | L9: =(D9-D8)/D8*100 -> 1.2823563 | M9: {=TREND($D$2:$D$26,$A$2:$A$26,A9)} -> 1615581.2 | N9: =(D9-M9)/M9*100 -> 5.297926 | O9: =(E9-E8)/E8*100 -> 1.8297411 | P9: =(H9-H8)/H8*100 -> 2.4670754 | Q9: =B9-B8 -> -0.7 | R9: =AVERAGE($B$2:$B$26) -> 9.2 | S9: =B9-R9 -> -3
A10: 39448 | B10: 6.8 | C10: 1643974 | D10: 1683152 | E10: 90.893968 | F10: 59211181 | H10: =C10/D10*100 -> 97.672343 | I10: =H10/$H$2*100 -> 123.42686 | J10: =(D10*1000000)/F10 -> 28426.253 | K10: =J10/$J$2*100 -> 102.83749 | L10: =(D10-D9)/D9*100 -> -1.059357 | M10: {=TREND($D$2:$D$26,$A$2:$A$26,A10)} -> 1616385.1 | N10: =(D10-M10)/M10*100 -> 4.1306303 | O10: =(E10-E9)/E9*100 -> 3.3478326 | P10: =(H10-H9)/H9*100 -> 2.4044703 | Q10: =B10-B9 -> 0.6 | R10: =AVERAGE($B$2:$B$26) -> 9.2 | S10: =B10-R10 -> -2.4
A11: 39814 | B11: 7.9 | C11: 1584007 | D11: 1593498 | E11: 91.598186 | F11: 59555454 | H11: =C11/D11*100 -> 99.404392 | I11: =H11/$H$2*100 -> 125.61562 | J11: =(D11*1000000)/F11 -> 26756.542 | K11: =J11/$J$2*100 -> 96.796985 | L11: =(D11-D10)/D10*100 -> -5.326554 | M11: {=TREND($D$2:$D$26,$A$2:$A$26,A11)} -> 1617191.2 | N11: =(D11-M11)/M11*100 -> -1.4650843 | O11: =(E11-E10)/E10*100 -> 0.77476813 | P11: =(H11-H10)/H10*100 -> 1.7733257 | Q11: =B11-B10 -> 1.1 | R11: =AVERAGE($B$2:$B$26) -> 9.2 | S11: =B11-R11 -> -1.3
A12: 40179 | B12: 8.5 | C12: 1617083 | D12: 1617083.2 | E12: 92.995531 | F12: 59819407 | H12: =C12/D12*100 -> 99.999988 | I12: =H12/$H$2*100 -> 126.36827 | J12: =(D12*1000000)/F12 -> 27032.752 | K12: =J12/$J$2*100 -> 97.796229 | L12: =(D12-D11)/D11*100 -> 1.4800897 | M12: {=TREND($D$2:$D$26,$A$2:$A$26,A12)} -> 1617995.1 | N12: =(D12-M12)/M12*100 -> -0.056361011 | O12: =(E12-E11)/E11*100 -> 1.525516 | P12: =(H12-H11)/H11*100 -> 0.5991642 | Q12: =B12-B11 -> 0.6 | R12: =AVERAGE($B$2:$B$26) -> 9.2 | S12: =B12-R12 -> -0.7
A13: 40544 | B13: 8.6 | C13: 1659112 | D13: 1630941 | E13: 95.581395 | F13: 60026841 | H13: =C13/D13*100 -> 101.72729 | I13: =H13/$H$2*100 -> 128.55102 | J13: =(D13*1000000)/F13 -> 27170.195 | K13: =J13/$J$2*100 -> 98.293457 | L13: =(D13-D12)/D12*100 -> 0.85696271 | M13: {=TREND($D$2:$D$26,$A$2:$A$26,A13)} -> 1618799 | N13: =(D13-M13)/M13*100 -> 0.75006082 | O13: =(E13-E12)/E12*100 -> 2.7806327 | P13: =(H13-H12)/H12*100 -> 1.7272976 | Q13: =B13-B12 -> 0.1 | R13: =AVERAGE($B$2:$B$26) -> 9.2 | S13: =B13-R13 -> -0.6
A14: 40909 | B14: 10.9 | C14: 1633776 | D14: 1579157.7 | E14: 98.488372 | F14: 60191247 | H14: =C14/D14*100 -> 103.4587 | I14: =H14/$H$2*100 -> 130.73898 | J14: =(D14*1000000)/F14 -> 26235.67 | K14: =J14/$J$2*100 -> 94.91263 | L14: =(D14-D13)/D13*100 -> -3.1750566 | M14: {=TREND($D$2:$D$26,$A$2:$A$26,A14)} -> 1619602.9 | N14: =(D14-M14)/M14*100 -> -2.497231 | O14: =(E14-E13)/E13*100 -> 3.0413633 | P14: =(H14-H13)/H13*100 -> 1.7020146 | Q14: =B14-B13 -> 2.3 | R14: =AVERAGE($B$2:$B$26) -> 9.2 | S14: =B14-R14 -> 1.7
... A26: 45292 | B26: 6.6 | C26: 2199105 | D26: 1721090.6 | E26: 120.78333 | F26: 58952704 | H26: =C26/D26*100 -> 127.77392 | I26: =H26/$H$2*100 -> 161.46571 | J26: =(D26*1000000)/F26 -> 29194.43 | K26: =J26/$J$2*100 -> 105.61652 | L26: =(D26-D25)/D25*100 -> 0.58635074 | M26: {=TREND($D$2:$D$26,$A$2:$A$26,A26)} -> 1629256.4 | N26: =(D26-M26)/M26*100 -> 5.6365722 | O26: =(E26-E25)/E25*100 -> 0.98237302 | P26: =(H26-H25)/H25*100 -> 1.970949 | Q26: =B26-B25 -> -1.1 | R26: =AVERAGE($B$2:$B$26) -> 9.2 | S26: =B26-R26 -> -2.6
A27: Data Sources | B27: FRED `LRHUTTTTITM156S` | C27: FRED `CPMNACSCAB1GQIT` | D27: FRED `CLVMNACSCAB1GQIT` | E27: FRED `ITACPIALLMINMEI` | F27: FRED `POPTOTITA647NWDB` | H27: Excel formula | I27: Excel formula | J27: Excel formula | K27: Excel formula | L27: Excel formula | M27: Excel formula | N27: Excel formula | O27: Excel formula | P27: Excel formula | Q27: Excel formula | R27: Excel formula | S27: Excel formula
H28: Nominal GDP / Real GDP × 100 | I28: GDP Deflator / GDP Deflator in 2000 × 100 | J28: (Real GDP × 1,000,000) / Population → EUR/person | K28: Real GDP per Capita / 2000 value × 100 | L28: (Real GDP_t − Real GDP_t−1) / Real GDP_t−1 × 100 | M28: TREND(Real GDP 2000–2024, time 2000–2024) | N28: (Actual Real GDP − Potential GDP) / Potential GDP × 100 | O28: (CPI_t − CPI_t−1) / CPI_t−1 × 100 | P28: (Deflator_t − Deflator_t−1) / Deflator_t−1 × 100 | Q28: Unemployment_t − Unemployment_t−1 | R28: AVERAGE(Unemployment, 2000–2024) | S28: Actual unemployment − full-sample average
A29: sample period | B29: 2000–2024 | C29: 2000–2024 | D29: 2000–2024 | E29: 2000–2024 | F29: 2000–2024 | G29: valid | H29: 2000–2024 | I29: 2000–2024 | J29: 2000–2024 | K29: 2000–2024 | L29: 2001–2024 | M29: 2000–2024 | N29: 2000–2024 | O29: 2001–2024 | P29: 2001–2024 | Q29: 2001–2024 | R29: 2000–2024 | S29: 2000–2024
A30: type | B30: Monthly harmonized unemployment rate (%) | C30: Quarterly nominal GDP (million EUR) | D30: Quarterly real GDP (million chained EUR) | E30: Monthly CPI index (2015 = 100) | F30: Annual population (persons) | G30: inputs | H30: C, D | I30: H | J30: D, F | K30: J | L30: D | M30: A, D | N30: D, M | O30: E | P30: H | Q30: B | R30: B | S30: B, R
A31: Data processing | B31: Converted to annual using the annual average. | C31: Four quarterly values were summed to obtain each annual GDP value. | D31: Four quarterly values were summed to obtain each annual real GDP value. | E31: Converted to annual using the annual average. | F31: Already annual; no frequency conversion. | G31: purpose | H31: Implicit price index for domestic output. | I31: Re-bases each country's deflator so 2000 = 100 for comparison. | J31: Converts GDP from millions of EUR to EUR before dividing by persons. | K31: Measures cumulative real-GDP-per-capita growth since 2000. | L31: Year-over-year real output growth. | M31: Full-sample linear trend used as the homework proxy for potential GDP. | N31: Measures actual output relative to the linear-trend proxy. | O31: Annual CPI inflation. | P31: Annual inflation implied by the GDP deflator. | Q31: Percentage-point change in unemployment; used in Okun scatter plot. | R31: Simple benchmark for the 'normal' unemployment rate in Q9. | S31: Positive values mean unemployment is above its 2000–2024 average.

Sheet France
A1: Year | B1: Unemployment rate | C1: Nominal GDP | D1: Real GDP | E1: CPI( base = 2015) | F1: Population(person) | H1: GDP Deflator | I1: GDP Deflator Index (2000=100) | J1: Real GDP per Capita (EUR/person) | K1: Real GDP per Capita Index (2000=100) | L1: Real GDP Growth (%) | M1: Potential GDP (Linear Trend) | N1: Output Gap (%) | O1: CPI Inflation Rate (%) | P1: GDP Deflator Inflation Rate (%) | Q1: Change in Unemployment Rate (pp) | R1: Average Unemployment Rate (%) | S1: Unemployment Gap (pp)
A2: 36526 | B2: 9.2 | C2: 1475503.3 | D2: 1750227.2 | E2: 79.929167 | F2: 60918661 | H2: =C2/D2*100 -> 84.303529 | I2: =H2/$H$2*100 -> 100 | J2: =(D2*1000000)/F2 -> 28730.559 | K2: =J2/$J$2*100 -> 100 | M2: {=TREND($D$2:$D$26,$A$2:$A$26,A2)} -> 1778794.2 | N2: =(D2-M2)/M2*100 -> -1.6059782 | R2: =AVERAGE($B$2:$B$26) -> 8.792 | S2: =B2-R2 -> 0.408
A3: 36892 | B3: 8.5 | C3: 1531244.5 | D3: 1782380.2 | E3: 81.235833 | F3: 61364377 | H3: =C3/D3*100 -> 85.910094 | I3: =H3/$H$2*100 -> 101.90569 | J3: =(D3*1000000)/F3 -> 29045.845 | K3: =J3/$J$2*100 -> 101.09739 | L3: =(D3-D2)/D2*100 -> 1.8370758 | M3: {=TREND($D$2:$D$26,$A$2:$A$26,A3)} -> 1801425.5 | N3: =(D3-M3)/M3*100 -> -1.0572372 | O3: =(E3-E2)/E2*100 -> 1.6347808 | P3: =(H3-H2)/H2*100 -> 1.9056906 | Q3: =B3-B2 -> -0.7 | R3: =AVERAGE($B$2:$B$26) -> 8.792 | S3: =B3-R3 -> -0.292
A4: 37257 | B4: 8.3 | C4: 1580459.7 | D4: 1802458.8 | E4: 82.798333 | F4: 61812142 | H4: =C4/D4*100 -> 87.683541 | I4: =H4/$H$2*100 -> 104.00934 | J4: =(D4*1000000)/F4 -> 29160.271 | K4: =J4/$J$2*100 -> 101.49566 | L4: =(D4-D3)/D3*100 -> 1.1265049 | M4: {=TREND($D$2:$D$26,$A$2:$A$26,A4)} -> 1823995 | N4: =(D4-M4)/M4*100 -> -1.180716 | O4: =(E4-E3)/E3*100 -> 1.9234123 | P4: =(H4-H3)/H3*100 -> 2.064306 | Q4: =B4-B3 -> -0.2 | R4: =AVERAGE($B$2:$B$26) -> 8.792 | S4: =B4-R4 -> -0.492
A5: 37622 | B5: 8.5 | C5: 1624806.1 | D5: 1820279.2 | E5: 84.535833 | F5: 62249855 | H5: =C5/D5*100 -> 89.261367 | I5: =H5/$H$2*100 -> 105.88094 | J5: =(D5*1000000)/F5 -> 29241.501 | K5: =J5/$J$2*100 -> 101.77839 | L5: =(D5-D4)/D4*100 -> 0.9886717 | M5: {=TREND($D$2:$D$26,$A$2:$A$26,A5)} -> 1846564.5 | N5: =(D5-M5)/M5*100 -> -1.4234683 | O5: =(E5-E4)/E4*100 -> 2.0984722 | P5: =(H5-H4)/H4*100 -> 1.7994554 | Q5: =B5-B4 -> 0.2 | R5: =AVERAGE($B$2:$B$26) -> 8.792 | S5: =B5-R5 -> -0.292
A6: 37987 | B6: 8.9 | C6: 1692878.6 | D6: 1866127.3 | E6: 86.346667 | F6: 62707588 | H6: =C6/D6*100 -> 90.716137 | I6: =H6/$H$2*100 -> 107.60657 | J6: =(D6*1000000)/F6 -> 29759.194 | K6: =J6/$J$2*100 -> 103.58028 | L6: =(D6-D5)/D5*100 -> 2.51874 | M6: {=TREND($D$2:$D$26,$A$2:$A$26,A6)} -> 1869133.9 | N6: =(D6-M6)/M6*100 -> -0.16085625 | O6: =(E6-E5)/E5*100 -> 2.1420896 | P6: =(H6-H5)/H5*100 -> 1.6297868 | Q6: =B6-B5 -> 0.4 | R6: =AVERAGE($B$2:$B$26) -> 8.792 | S6: =B6-R6 -> 0.108
A7: 38353 | B7: 8.9 | C7: 1760519.9 | D7: 1903204.7 | E7: 87.854167 | F7: 63180854 | H7: =C7/D7*100 -> 92.502919 | I7: =H7/$H$2*100 -> 109.72603 | J7: =(D7*1000000)/F7 -> 30123.124 | K7: =J7/$J$2*100 -> 104.84698 | L7: =(D7-D6)/D6*100 -> 1.9868634 | M7: {=TREND($D$2:$D$26,$A$2:$A$26,A7)} -> 1891765.2 | N7: =(D7-M7)/M7*100 -> 0.60469914 | O7: =(E7-E6)/E6*100 -> 1.7458694 | P7: =(H7-H6)/H6*100 -> 1.9696405 | Q7: =B7-B6 -> 0 | R7: =AVERAGE($B$2:$B$26) -> 8.792 | S7: =B7-R7 -> 0.108
A8: 38718 | B8: 8.9 | C8: 1848255.5 | D8: 1959090.6 | E8: 89.325833 | F8: 63622342 | H8: =C8/D8*100 -> 94.342523 | I8: =H8/$H$2*100 -> 111.90815 | J8: =(D8*1000000)/F8 -> 30792.494 | K8: =J8/$J$2*100 -> 107.1768 | L8: =(D8-D7)/D7*100 -> 2.9364104 | M8: {=TREND($D$2:$D$26,$A$2:$A$26,A8)} -> 1914334.7 | N8: =(D8-M8)/M8*100 -> 2.3379365 | O8: =(E8-E7)/E7*100 -> 1.6751245 | P8: =(H8-H7)/H7*100 -> 1.9886984 | Q8: =B8-B7 -> 0 | R8: =AVERAGE($B$2:$B$26) -> 8.792 | S8: =B8-R8 -> 0.108
A9: 39083 | B9: 8 | C9: 1939249.6 | D9: 2007651.7 | E9: 90.655 | F9: 64016890 | H9: =C9/D9*100 -> 96.59293 | I9: =H9/$H$2*100 -> 114.57756 | J9: =(D9*1000000)/F9 -> 31361.281 | K9: =J9/$J$2*100 -> 109.15653 | L9: =(D9-D8)/D8*100 -> 2.4787572 | M9: {=TREND($D$2:$D$26,$A$2:$A$26,A9)} -> 1936904.1 | N9: =(D9-M9)/M9*100 -> 3.6526108 | O9: =(E9-E8)/E8*100 -> 1.4879981 | P9: =(H9-H8)/H8*100 -> 2.385358 | Q9: =B9-B8 -> -0.9 | R9: =AVERAGE($B$2:$B$26) -> 8.792 | S9: =B9-R9 -> -0.792
A10: 39448 | B10: 7.4 | C10: 1989014.9 | D10: 2012887 | E10: 93.205 | F10: 64375116 | H10: =C10/D10*100 -> 98.814037 | I10: =H10/$H$2*100 -> 117.21222 | J10: =(D10*1000000)/F10 -> 31268.091 | K10: =J10/$J$2*100 -> 108.83217 | L10: =(D10-D9)/D9*100 -> 0.26076734 | M10: {=TREND($D$2:$D$26,$A$2:$A$26,A10)} -> 1959473.6 | N10: =(D10-M10)/M10*100 -> 2.7259061 | O10: =(E10-E9)/E9*100 -> 2.8128619 | P10: =(H10-H9)/H9*100 -> 2.2994507 | Q10: =B10-B9 -> -0.6 | R10: =AVERAGE($B$2:$B$26) -> 8.792 | S10: =B10-R10 -> -1.392
A11: 39814 | B11: 9.1 | C11: 1936988.9 | D11: 1958036.5 | E11: 93.286667 | F11: 64706436 | H11: =C11/D11*100 -> 98.925066 | I11: =H11/$H$2*100 -> 117.34392 | J11: =(D11*1000000)/F11 -> 30260.305 | K11: =J11/$J$2*100 -> 105.32446 | L11: =(D11-D10)/D10*100 -> -2.7249667 | M11: {=TREND($D$2:$D$26,$A$2:$A$26,A11)} -> 1982104.9 | N11: =(D11-M11)/M11*100 -> -1.214284 | O11: =(E11-E10)/E10*100 -> 0.087620478 | P11: =(H11-H10)/H10*100 -> 0.11236182 | Q11: =B11-B10 -> 1.7 | R11: =AVERAGE($B$2:$B$26) -> 8.792 | S11: =B11-R11 -> 0.308
A12: 40179 | B12: 9.3 | C12: 1993991.5 | D12: 1993991.5 | E12: 94.715 | F12: 65026211 | H12: =C12/D12*100 -> 100 | I12: =H12/$H$2*100 -> 118.619 | J12: =(D12*1000000)/F12 -> 30664.427 | K12: =J12/$J$2*100 -> 106.73105 | L12: =(D12-D11)/D11*100 -> 1.8362783 | M12: {=TREND($D$2:$D$26,$A$2:$A$26,A12)} -> 2004674.3 | N12: =(D12-M12)/M12*100 -> -0.53289661 | O12: =(E12-E11)/E11*100 -> 1.5311227 | P12: =(H12-H11)/H11*100 -> 1.0866144 | Q12: =B12-B11 -> 0.2 | R12: =AVERAGE($B$2:$B$26) -> 8.792 | S12: =B12-R12 -> 0.508
A13: 40544 | B13: 9.2 | C13: 2060977.1 | D13: 2043487.9 | E13: 96.715 | F13: 65340830 | H13: =C13/D13*100 -> 100.85585 | I13: =H13/$H$2*100 -> 119.6342 | J13: =(D13*1000000)/F13 -> 31274.287 | K13: =J13/$J$2*100 -> 108.85374 | L13: =(D13-D12)/D12*100 -> 2.4822774 | M13: {=TREND($D$2:$D$26,$A$2:$A$26,A13)} -> 2027243.8 | N13: =(D13-M13)/M13*100 -> 0.80128988 | O13: =(E13-E12)/E12*100 -> 2.111598 | P13: =(H13-H12)/H12*100 -> 0.85585043 | Q13: =B13-B12 -> -0.1 | R13: =AVERAGE($B$2:$B$26) -> 8.792 | S13: =B13-R13 -> 0.408
A14: 40909 | B14: 9.8 | C14: 2087960 | D14: 2048137.5 | E14: 98.605 | F14: 65657659 | H14: =C14/D14*100 -> 101.94433 | I14: =H14/$H$2*100 -> 120.92534 | J14: =(D14*1000000)/F14 -> 31194.19 | K14: =J14/$J$2*100 -> 108.57495 | L14: =(D14-D13)/D13*100 -> 0.22753254 | M14: {=TREND($D$2:$D$26,$A$2:$A$26,A14)} -> 2049813.3 | N14: =(D14-M14)/M14*100 -> -0.081751823 | O14: =(E14-E13)/E13*100 -> 1.9541953 | P14: =(H14-H13)/H13*100 -> 1.0792404 | Q14: =B14-B13 -> 0.6 | R14: =AVERAGE($B$2:$B$26) -> 8.792 | S14: =B14-R14 -> 1.008
... A26: 45292 | B26: 7.5 | C26: 2936861.9 | D26: 2360180.8 | E26: 119.82083 | F26: 68551653 | H26: =C26/D26*100 -> 124.43377 | I26: =H26/$H$2*100 -> 147.60209 | J26: =(D26*1000000)/F26 -> 34429.233 | K26: =J26/$J$2*100 -> 119.83488 | L26: =(D26-D25)/D25*100 -> 1.4263884 | M26: {=TREND($D$2:$D$26,$A$2:$A$26,A26)} -> 2320832.3 | N26: =(D26-M26)/M26*100 -> 1.6954491 | O26: =(E26-E25)/E25*100 -> 1.9990494 | P26: =(H26-H25)/H25*100 -> 2.0400277 | Q26: =B26-B25 -> 0.2 | R26: =AVERAGE($B$2:$B$26) -> 8.792 | S26: =B26-R26 -> -1.292
A27: Data Sources | B27: FRED `LRHUTTTTFRM156S` | C27: FRED `CPMNACSCAB1GQFR` | D27: FRED `CLVMNACSCAB1GQFR` | E27: FRED `FRACPIALLMINMEI` | F27: FRED `POPTOTFRA647NWDB` | H27: Excel formula | I27: Excel formula | J27: Excel formula | K27: Excel formula | L27: Excel formula | M27: Excel formula | N27: Excel formula | O27: Excel formula | P27: Excel formula | Q27: Excel formula | R27: Excel formula | S27: Excel formula
H28: Nominal GDP / Real GDP × 100 | I28: GDP Deflator / GDP Deflator in 2000 × 100 | J28: (Real GDP × 1,000,000) / Population → EUR/person | K28: Real GDP per Capita / 2000 value × 100 | L28: (Real GDP_t − Real GDP_t−1) / Real GDP_t−1 × 100 | M28: TREND(Real GDP 2000–2024, time 2000–2024) | N28: (Actual Real GDP − Potential GDP) / Potential GDP × 100 | O28: (CPI_t − CPI_t−1) / CPI_t−1 × 100 | P28: (Deflator_t − Deflator_t−1) / Deflator_t−1 × 100 | Q28: Unemployment_t − Unemployment_t−1 | R28: AVERAGE(Unemployment, 2000–2024) | S28: Actual unemployment − full-sample average
A29: sample period | B29: 2000–2024 | C29: 2000–2024 | D29: 2000–2024 | E29: 2000–2024 | F29: 2000–2024 | G29: valid | H29: 2000–2024 | I29: 2000–2024 | J29: 2000–2024 | K29: 2000–2024 | L29: 2001–2024 | M29: 2000–2024 | N29: 2000–2024 | O29: 2001–2024 | P29: 2001–2024 | Q29: 2001–2024 | R29: 2000–2024 | S29: 2000–2024
A30: type | B30: Monthly harmonized unemployment rate (%) | C30: Quarterly nominal GDP (million EUR) | D30: Quarterly real GDP (million chained EUR) | E30: Monthly CPI index (2015 = 100) | F30: Annual population (persons) | G30: inputs | H30: C, D | I30: H | J30: D, F | K30: J | L30: D | M30: A, D | N30: D, M | O30: E | P30: H | Q30: B | R30: B | S30: B, R
A31: Data processing | B31: Converted to annual using the annual average. | C31: Four quarterly values were summed to obtain each annual GDP value. | D31: Four quarterly values were summed to obtain each annual real GDP value. | E31: Converted to annual using the annual average. | F31: Already annual; no frequency conversion. | G31: purpose | H31: Implicit price index for domestic output. | I31: Re-bases each country's deflator so 2000 = 100 for comparison. | J31: Converts GDP from millions of EUR to EUR before dividing by persons. | K31: Measures cumulative real-GDP-per-capita growth since 2000. | L31: Year-over-year real output growth. | M31: Full-sample linear trend used as the homework proxy for potential GDP. | N31: Measures actual output relative to the linear-trend proxy. | O31: Annual CPI inflation. | P31: Annual inflation implied by the GDP deflator. | Q31: Percentage-point change in unemployment; used in Okun scatter plot. | R31: Simple benchmark for the 'normal' unemployment rate in Q9. | S31: Positive values mean unemployment is above its 2000–2024 average.

Sheet Japan
A1: Year | B1: Unemployment rate | C1: Nominal GDP | D1: Real GDP | E1: CPI( base = 2015) | F1: population(person) | G1: cpi inflation input | I1: GDP Deflator | J1: GDP Deflator Index (2000=100) | K1: Real GDP per Capita (Yen/person) | L1: Real GDP per Capita Index (2000=100) | M1: Real GDP Growth (%) | N1: Potential GDP (Linear Trend) | O1: Output Gap (%) | P1: CPI Inflation Rate (%) | Q1: GDP Deflator Inflation Rate (%) | R1: Change in Unemployment Rate (pp) | S1: Average Unemployment Rate (%) | T1: Unemployment Gap (pp)
A2: 36526 | B2: 4.7 | C2: 543737.3 | D2: 500719.1 | E2: =E3/(1+G3/100) -> 99.105126 | F2: 126843000 | G2: -0.67657868 | I2: =C2/D2*100 -> 108.59128 | J2: =I2/$I$2*100 -> 100 | K2: =(D2*1000000000)/F2 -> 3947550.1 | L2: =K2/$K$2*100 -> 100 | N2: {=TREND($D$2:$D$26,$A$2:$A$26,A2)} -> 502660.39 | O2: =(D2-N2)/N2*100 -> -0.38620322 | S2: =AVERAGE($B$2:$B$26) -> 3.816 | T2: =B2-S2 -> 0.884
A3: 36892 | B3: 5 | C3: 539711.5 | D3: 502075.6 | E3: =E4/(1+G4/100) -> 98.371693 | F3: 127149000 | G3: -0.7400555 | I3: =C3/D3*100 -> 107.49606 | J3: =I3/$I$2*100 -> 98.991428 | K3: =(D3*1000000000)/F3 -> 3948718.4 | L3: =K3/$K$2*100 -> 100.0296 | M3: =(D3-D2)/D2*100 -> 0.27091038 | N3: {=TREND($D$2:$D$26,$A$2:$A$26,A3)} -> 506252.46 | O3: =(D3-N3)/N3*100 -> -0.82505445 | P3: =(E3-E2)/E2*100 -> -0.7400555 | Q3: =(I3-I2)/I2*100 -> -1.0085724 | R3: =B3-B2 -> 0.3 | S3: =AVERAGE($B$2:$B$26) -> 3.816 | T3: =B3-S3 -> 1.184
A4: 37257 | B4: 5.4 | C4: 532463.2 | D4: 502338.3 | E4: =E5/(1+G5/100) -> 97.463237 | F4: 127445000 | G4: -0.92349403 | I4: =C4/D4*100 -> 105.99693 | J4: =I4/$I$2*100 -> 97.610905 | K4: =(D4*1000000000)/F4 -> 3941608.5 | L4: =K4/$K$2*100 -> 99.849487 | M4: =(D4-D3)/D3*100 -> 0.052322798 | N4: {=TREND($D$2:$D$26,$A$2:$A$26,A4)} -> 509834.71 | O4: =(D4-N4)/N4*100 -> -1.4703612 | P4: =(E4-E3)/E3*100 -> -0.92349403 | Q4: =(I4-I3)/I3*100 -> -1.3945884 | R4: =B4-B3 -> 0.4 | S4: =AVERAGE($B$2:$B$26) -> 3.816 | T4: =B4-S4 -> 1.584
A5: 37622 | B5: 5.2 | C5: 530387.4 | D5: 509455.1 | E5: =E6/(1+G6/100) -> 97.213203 | F5: 127718000 | G5: -0.25654182 | I5: =C5/D5*100 -> 104.10876 | J5: =I5/$I$2*100 -> 95.872117 | K5: =(D5*1000000000)/F5 -> 3988906 | L5: =K5/$K$2*100 -> 101.04763 | M5: =(D5-D4)/D4*100 -> 1.4167345 | N5: {=TREND($D$2:$D$26,$A$2:$A$26,A5)} -> 513416.97 | O5: =(D5-N5)/N5*100 -> -0.77166621 | P5: =(E5-E4)/E4*100 -> -0.25654182 | Q5: =(I5-I4)/I4*100 -> -1.7813461 | R5: =B5-B4 -> -0.2 | S5: =AVERAGE($B$2:$B$26) -> 3.816 | T5: =B5-S5 -> 1.384
A6: 37987 | B6: 4.7 | C6: 534603.7 | D6: 520164.7 | E6: =E7/(1+G7/100) -> 97.204868 | F6: 127761000 | G6: -0.0085733882 | I6: =C6/D6*100 -> 102.77585 | J6: =I6/$I$2*100 -> 94.64466 | K6: =(D6*1000000000)/F6 -> 4071388.8 | L6: =K6/$K$2*100 -> 103.1371 | M6: =(D6-D5)/D5*100 -> 2.1021676 | N6: {=TREND($D$2:$D$26,$A$2:$A$26,A6)} -> 516999.22 | O6: =(D6-N6)/N6*100 -> 0.61227971 | P6: =(E6-E5)/E5*100 -> -0.0085733882 | Q6: =(I6-I5)/I5*100 -> -1.2803062 | R6: =B6-B5 -> -0.5 | S6: =AVERAGE($B$2:$B$26) -> 3.816 | T6: =B6-S6 -> 0.884
A7: 38353 | B7: 4.4 | C7: 537485.5 | D7: 529762 | E7: =E8/(1+G8/100) -> 96.929831 | F7: 127773000 | G7: -0.28294607 | I7: =C7/D7*100 -> 101.45792 | J7: =I7/$I$2*100 -> 93.430997 | K7: =(D7*1000000000)/F7 -> 4146118.5 | L7: =K7/$K$2*100 -> 105.03017 | M7: =(D7-D6)/D6*100 -> 1.8450502 | N7: {=TREND($D$2:$D$26,$A$2:$A$26,A7)} -> 520591.29 | O7: =(D7-N7)/N7*100 -> 1.7615957 | P7: =(E7-E6)/E6*100 -> -0.28294607 | Q7: =(I7-I6)/I6*100 -> -1.282337 | R7: =B7-B6 -> -0.3 | S7: =AVERAGE($B$2:$B$26) -> 3.816 | T7: =B7-S7 -> 0.584
A8: 38718 | B8: 4.1 | C8: 540568.1 | D8: 537815.5 | E8: =E9/(1+G9/100) -> 97.17153 | F8: 127854000 | G8: 0.24935512 | I8: =C8/D8*100 -> 100.51181 | J8: =I8/$I$2*100 -> 92.559741 | K8: =(D8*1000000000)/F8 -> 4206481.6 | L8: =K8/$K$2*100 -> 106.5593 | M8: =(D8-D7)/D7*100 -> 1.520211 | N8: {=TREND($D$2:$D$26,$A$2:$A$26,A8)} -> 524173.54 | O8: =(D8-N8)/N8*100 -> 2.6025656 | P8: =(E8-E7)/E7*100 -> 0.24935512 | Q8: =(I8-I7)/I7*100 -> -0.93251236 | R8: =B8-B7 -> -0.3 | S8: =AVERAGE($B$2:$B$26) -> 3.816 | T8: =B8-S8 -> 0.284
A9: 39083 | B9: 3.8 | C9: 544628.1 | D9: 547072.8 | E9: =E10/(1+G10/100) -> 97.229872 | F9: 128001000 | G9: 0.060039454 | I9: =C9/D9*100 -> 99.553131 | J9: =I9/$I$2*100 -> 91.676907 | K9: =(D9*1000000000)/F9 -> 4273972.9 | L9: =K9/$K$2*100 -> 108.269 | M9: =(D9-D8)/D8*100 -> 1.721278 | N9: {=TREND($D$2:$D$26,$A$2:$A$26,A9)} -> 527755.79 | O9: =(D9-N9)/N9*100 -> 3.6602169 | P9: =(E9-E8)/E8*100 -> 0.060039454 | Q9: =(I9-I8)/I8*100 -> -0.95379879 | R9: =B9-B8 -> -0.3 | S9: =AVERAGE($B$2:$B$26) -> 3.816 | T9: =B9-S9 -> -0.016
A10: 39448 | B10: 4 | C10: 533458.9 | D10: 540731.3 | E10: =E11/(1+G11/100) -> 98.571721 | F10: 128063000 | G10: 1.3800789 | I10: =C10/D10*100 -> 98.655081 | J10: =I10/$I$2*100 -> 90.849907 | K10: =(D10*1000000000)/F10 -> 4222385.1 | L10: =K10/$K$2*100 -> 106.96217 | M10: =(D10-D9)/D9*100 -> -1.1591693 | N10: {=TREND($D$2:$D$26,$A$2:$A$26,A10)} -> 531338.05 | O10: =(D10-N10)/N10*100 -> 1.7678488 | P10: =(E10-E9)/E9*100 -> 1.3800789 | Q10: =(I10-I9)/I9*100 -> -0.90208127 | R10: =B10-B9 -> 0.2 | S10: =AVERAGE($B$2:$B$26) -> 3.816 | T10: =B10-S10 -> 0.184
A11: 39814 | B11: 5.1 | C11: 499514.1 | D11: 508634.2 | E11: =E12/(1+G12/100) -> 97.238206 | F11: 128047000 | G11: -1.3528367 | I11: =C11/D11*100 -> 98.206943 | J11: =I11/$I$2*100 -> 90.437224 | K11: =(D11*1000000000)/F11 -> 3972246.1 | L11: =K11/$K$2*100 -> 100.6256 | M11: =(D11-D10)/D10*100 -> -5.9358687 | N11: {=TREND($D$2:$D$26,$A$2:$A$26,A11)} -> 534930.11 | O11: =(D11-N11)/N11*100 -> -4.9157663 | P11: =(E11-E10)/E10*100 -> -1.3528367 | Q11: =(I11-I10)/I10*100 -> -0.45424666 | R11: =B11-B10 -> 1.1 | S11: =AVERAGE($B$2:$B$26) -> 3.816 | T11: =B11-S11 -> 1.284
A12: 40179 | B12: 5.1 | C12: 510315.6 | D12: 529650.2 | E12: =E13/(1+G13/100) -> 96.530076 | F12: 128070000 | G12: -0.72824321 | I12: =C12/D12*100 -> 96.349553 | J12: =I12/$I$2*100 -> 88.726783 | K12: =(D12*1000000000)/F12 -> 4135630.5 | L12: =K12/$K$2*100 -> 104.76448 | M12: =(D12-D11)/D11*100 -> 4.1318496 | N12: {=TREND($D$2:$D$26,$A$2:$A$26,A12)} -> 538512.37 | O12: =(D12-N12)/N12*100 -> -1.6456758 | P12: =(E12-E11)/E11*100 -> -0.72824321 | Q12: =(I12-I11)/I11*100 -> -1.8913024 | R12: =B12-B11 -> 0 | S12: =AVERAGE($B$2:$B$26) -> 3.816 | T12: =B12-S12 -> 1.284
A13: 40544 | B13: 4.6 | C13: 501412.3 | D13: 528667.5 | E13: =E14/(1+G14/100) -> 96.267074 | F13: 127833000 | G13: -0.27245562 | I13: =C13/D13*100 -> 94.844548 | J13: =I13/$I$2*100 -> 87.340848 | K13: =(D13*1000000000)/F13 -> 4135610.5 | L13: =K13/$K$2*100 -> 104.76398 | M13: =(D13-D12)/D12*100 -> -0.18553755 | N13: {=TREND($D$2:$D$26,$A$2:$A$26,A13)} -> 542094.62 | O13: =(D13-N13)/N13*100 -> -2.4768963 | P13: =(E13-E12)/E12*100 -> -0.27245562 | Q13: =(I13-I12)/I12*100 -> -1.5620261 | R13: =B13-B12 -> -0.5 | S13: =AVERAGE($B$2:$B$26) -> 3.816 | T13: =B13-S13 -> 0.784
A14: 40909 | B14: 4.3 | C14: 505530 | D14: 537424 | E14: =E15/(1+G15/100) -> 96.224654 | F14: 127629000 | G14: -0.04406451 | I14: =C14/D14*100 -> 94.065393 | J14: =I14/$I$2*100 -> 86.623337 | K14: =(D14*1000000000)/F14 -> 4210829.8 | L14: =K14/$K$2*100 -> 106.66945 | M14: =(D14-D13)/D13*100 -> 1.6563341 | N14: {=TREND($D$2:$D$26,$A$2:$A$26,A14)} -> 545676.87 | O14: =(D14-N14)/N14*100 -> -1.5124106 | P14: =(E14-E13)/E13*100 -> -0.04406451 | Q14: =(I14-I13)/I13*100 -> -0.82150681 | R14: =B14-B13 -> -0.3 | S14: =AVERAGE($B$2:$B$26) -> 3.816 | T14: =B14-S14 -> 0.484
... A16: 41640 | B16: 3.6 | C16: 528094.1 | D16: 552778.6 | E16: =E17/(1+G17/100) -> 99.210995 | F16: 127276000 | G16: 2.7592267 | I16: =C16/D16*100 -> 95.534469 | J16: =I16/$I$2*100 -> 87.976185 | K16: =(D16*1000000000)/F16 -> 4343148.7 | L16: =K16/$K$2*100 -> 110.02137 | M16: =(D16-D15)/D15*100 -> 0.81909567 | N16: {=TREND($D$2:$D$26,$A$2:$A$26,A16)} -> 552851.2 | O16: =(D16-N16)/N16*100 -> -0.01313121 | P16: =(E16-E15)/E15*100 -> 2.7592267 | Q16: =(I16-I15)/I15*100 -> 1.7453236 | R16: =B16-B15 -> -0.4 | S16: =AVERAGE($B$2:$B$26) -> 3.816 | T16: =B16-S16 -> -0.216
